mplus_output/bi-19-ELSA_W5.out
Mplus VERSION 8.1 (Mac)
MUTHEN & MUTHEN
04/23/2020  10:57 PM

INPUT INSTRUCTIONS

  DATA:
  FILE = "bi-19-ELSA_W5.dat";

  VARIABLE:
  NAMES = mplusid UDAT UDAY UMON UYER UIWR UDWR UANI ULET UHL1 UHL2 UHL3 UHL4 UPM3;
   MISSING=.;
   CATEGORICAL ARE all; idvariable = mplusid;
  ANALYSIS:
  estimator = wlsmv; coverage=0;
  MODEL:
  g by UDAT * ;
   g by UDAY * ;
   g by UMON * ;
   g by UYER * ;
   g by UIWR * ;
   g by UDWR * ;
   g by UANI * ;
   g by ULET * ;
   g by UPM3 * ;
   g by UHL1 * ;
   g by UHL2 * ;
   g by UHL3 * ;
   g by UHL4 * ;
   s1 by UIWR @ 1 ;
   s1 by UDWR @ 1 ;
   g @ 1;
   s1 * ;
   g with s1 @ 0 ;

  OUTPUT:
  standardized; svalues;



*** WARNING
  Data set contains cases with missing on all variables.
  These cases were not included in the analysis.
  Number of cases with missing on all variables:  574
   1 WARNING(S) FOUND IN THE INPUT INSTRUCTIONS




SUMMARY OF ANALYSIS

Number of groups                                                 1
Number of observations                                        9700

Number of dependent variables                                   13
Number of independent variables                                  0
Number of continuous latent variables                            2

Observed dependent variables

  Binary and ordered categorical (ordinal)
   UDAT        UDAY        UMON        UYER        UIWR        UDWR
   UANI        ULET        UHL1        UHL2        UHL3        UHL4
   UPM3

Continuous latent variables
   G           S1

Variables with special functions

  ID variable           MPLUSID

Estimator                                                    WLSMV
Maximum number of iterations                                  1000
Convergence criterion                                    0.500D-04
Maximum number of steepest descent iterations                   20
Maximum number of iterations for H1                           2000
Convergence criterion for H1                             0.100D-03
Parameterization                                             DELTA
Link                                                        PROBIT

Input data file(s)
  bi-19-ELSA_W5.dat

Input data format  FREE


SUMMARY OF DATA

     Number of missing data patterns            29


COVARIANCE COVERAGE OF DATA

Minimum covariance coverage value   0.000


     PROPORTION OF DATA PRESENT


           Covariance Coverage
              UDAT          UDAY          UMON          UYER          UIWR
              ________      ________      ________      ________      ________
 UDAT           0.997
 UDAY           0.997         0.997
 UMON           0.997         0.997         0.997
 UYER           0.997         0.997         0.997         0.997
 UIWR           0.996         0.996         0.996         0.996         0.999
 UDWR           0.996         0.996         0.996         0.996         0.999
 UANI           0.995         0.995         0.995         0.995         0.996
 ULET           0.934         0.934         0.934         0.934         0.934
 UHL1           0.957         0.957         0.957         0.957         0.958
 UHL2           0.957         0.957         0.957         0.957         0.958
 UHL3           0.957         0.957         0.957         0.957         0.958
 UHL4           0.957         0.957         0.957         0.957         0.957
 UPM3           0.899         0.899         0.899         0.899         0.899


           Covariance Coverage
              UDWR          UANI          ULET          UHL1          UHL2
              ________      ________      ________      ________      ________
 UDWR           0.999
 UANI           0.996         0.996
 ULET           0.934         0.934         0.934
 UHL1           0.958         0.957         0.919         0.958
 UHL2           0.958         0.957         0.920         0.957         0.958
 UHL3           0.958         0.957         0.919         0.957         0.957
 UHL4           0.957         0.957         0.919         0.957         0.957
 UPM3           0.899         0.899         0.864         0.885         0.885


           Covariance Coverage
              UHL3          UHL4          UPM3
              ________      ________      ________
 UHL3           0.958
 UHL4           0.957         0.957
 UPM3           0.885         0.885         0.899


UNIVARIATE PROPORTIONS AND COUNTS FOR CATEGORICAL VARIABLES

    UDAT
      Category 1    0.167         1616.000
      Category 2    0.833         8056.000
    UDAY
      Category 1    0.021          199.000
      Category 2    0.979         9473.000
    UMON
      Category 1    0.021          203.000
      Category 2    0.979         9468.000
    UYER
      Category 1    0.022          216.000
      Category 2    0.978         9456.000
    UIWR
      Category 1    0.015          145.000
      Category 2    0.018          173.000
      Category 3    0.014          135.000
      Category 4    0.040          388.000
      Category 5    0.102          993.000
      Category 6    0.434         4206.000
      Category 7    0.212         2051.000
      Category 8    0.114         1101.000
      Category 9    0.042          409.000
      Category 10    0.009           89.000
    UDWR
      Category 1    0.069          672.000
      Category 2    0.031          300.000
      Category 3    0.055          530.000
      Category 4    0.113         1091.000
      Category 5    0.186         1805.000
      Category 6    0.367         3560.000
      Category 7    0.104         1003.000
      Category 8    0.050          487.000
      Category 9    0.018          176.000
      Category 10    0.007           65.000
    UANI
      Category 1    0.015          149.000
      Category 2    0.004           42.000
      Category 3    0.021          206.000
      Category 4    0.080          772.000
      Category 5    0.192         1858.000
      Category 6    0.238         2300.000
      Category 7    0.216         2083.000
      Category 8    0.138         1329.000
      Category 9    0.059          566.000
      Category 10    0.037          357.000
    ULET
      Category 1    0.009           83.000
      Category 2    0.033          301.000
      Category 3    0.095          862.000
      Category 4    0.257         2331.000
      Category 5    0.241         2187.000
      Category 6    0.261         2367.000
      Category 7    0.049          441.000
      Category 8    0.029          267.000
      Category 9    0.010           95.000
      Category 10    0.014          124.000
    UHL1
      Category 1    0.027          255.000
      Category 2    0.973         9033.000
    UHL2
      Category 1    0.158         1468.000
      Category 2    0.842         7822.000
    UHL3
      Category 1    0.081          748.000
      Category 2    0.919         8540.000
    UHL4
      Category 1    0.129         1198.000
      Category 2    0.871         8087.000
    UPM3
      Category 1    0.025          221.000
      Category 2    0.243         2122.000
      Category 3    0.011           99.000
      Category 4    0.027          235.000
      Category 5    0.693         6042.000



THE MODEL ESTIMATION TERMINATED NORMALLY



MODEL FIT INFORMATION

Number of Free Parameters                       62

Chi-Square Test of Model Fit

          Value                           1511.613*
          Degrees of Freedom                    64
          P-Value                           0.0000

*   The chi-square value for MLM, MLMV, MLR, ULSMV, WLSM and WLSMV cannot be used
    for chi-square difference testing in the regular way.  MLM, MLR and WLSM
    chi-square difference testing is described on the Mplus website.  MLMV, WLSMV,
    and ULSMV difference testing is done using the DIFFTEST option.

RMSEA (Root Mean Square Error Of Approximation)

          Estimate                           0.048
          90 Percent C.I.                    0.046  0.050
          Probability RMSEA <= .05           0.907

CFI/TLI

          CFI                                0.974
