mplus_output/bi-20-ELSA_W6.out
Mplus VERSION 8.1 (Mac)
MUTHEN & MUTHEN
05/27/2020  10:28 PM

INPUT INSTRUCTIONS

  DATA:
  FILE = "bi-20-ELSA_W6.dat";

  VARIABLE:
  NAMES = mplusid UDAT UDAY UMON UYER UIWR UDWR UHL1 UHL2 UHL3 UHL4 URE2 URE3 URE4
       URE5 URE6;
   MISSING=.;
   CATEGORICAL ARE all; idvariable = mplusid;
  ANALYSIS:
  estimator = wlsmv; coverage=0;
  MODEL:
  g by UDAT * ;
   g by UDAY * ;
   g by UMON * ;
   g by UYER * ;
   g by UIWR * ;
   g by UDWR * ;
   g by URE3 * ;
   g by URE5 * ;
   g by URE6 * ;
   g by URE2 * ;
   g by URE4 * ;
   g by UHL1 * ;
   g by UHL2 * ;
   g by UHL3 * ;
   g by UHL4 * ;
   s1 by UIWR @ 1 ;
   s1 by UDWR @ 1 ;
   g @ 1;
   s1 * ;
   g with s1 @ 0 ;

  OUTPUT:
  standardized; svalues;



*** WARNING
  Data set contains cases with missing on all variables.
  These cases were not included in the analysis.
  Number of cases with missing on all variables:  624
   1 WARNING(S) FOUND IN THE INPUT INSTRUCTIONS




SUMMARY OF ANALYSIS

Number of groups                                                 1
Number of observations                                        9977

Number of dependent variables                                   15
Number of independent variables                                  0
Number of continuous latent variables                            2

Observed dependent variables

  Binary and ordered categorical (ordinal)
   UDAT        UDAY        UMON        UYER        UIWR        UDWR
   UHL1        UHL2        UHL3        UHL4        URE2        URE3
   URE4        URE5        URE6

Continuous latent variables
   G           S1

Variables with special functions

  ID variable           MPLUSID

Estimator                                                    WLSMV
Maximum number of iterations                                  1000
Convergence criterion                                    0.500D-04
Maximum number of steepest descent iterations                   20
Maximum number of iterations for H1                           2000
Convergence criterion for H1                             0.100D-03
Parameterization                                             DELTA
Link                                                        PROBIT

Input data file(s)
  bi-20-ELSA_W6.dat

Input data format  FREE


SUMMARY OF DATA

     Number of missing data patterns            38


COVARIANCE COVERAGE OF DATA

Minimum covariance coverage value   0.000


     PROPORTION OF DATA PRESENT


           Covariance Coverage
              UDAT          UDAY          UMON          UYER          UIWR
              ________      ________      ________      ________      ________
 UDAT           0.993
 UDAY           0.993         0.993
 UMON           0.993         0.993         0.993
 UYER           0.993         0.993         0.993         0.993
 UIWR           0.993         0.993         0.993         0.993         0.999
 UDWR           0.993         0.993         0.993         0.993         0.999
 UHL1           0.149         0.149         0.149         0.149         0.149
 UHL2           0.149         0.149         0.149         0.149         0.149
 UHL3           0.149         0.149         0.149         0.149         0.149
 UHL4           0.149         0.149         0.149         0.149         0.149
 URE2           0.141         0.141         0.141         0.141         0.142
 URE3           0.135         0.135         0.135         0.135         0.135
 URE4           0.107         0.107         0.107         0.107         0.107
 URE5           0.106         0.106         0.106         0.106         0.106
 URE6           0.104         0.104         0.104         0.104         0.104


           Covariance Coverage
              UDWR          UHL1          UHL2          UHL3          UHL4
              ________      ________      ________      ________      ________
 UDWR           0.999
 UHL1           0.149         0.149
 UHL2           0.149         0.149         0.149
 UHL3           0.149         0.149         0.149         0.149
 UHL4           0.149         0.149         0.149         0.149         0.149
 URE2           0.142         0.120         0.120         0.120         0.120
 URE3           0.135         0.116         0.116         0.116         0.116
 URE4           0.107         0.092         0.092         0.092         0.092
 URE5           0.106         0.091         0.091         0.091         0.091
 URE6           0.104         0.090         0.090         0.090         0.090


           Covariance Coverage
              URE2          URE3          URE4          URE5          URE6
              ________      ________      ________      ________      ________
 URE2           0.142
 URE3           0.135         0.135
 URE4           0.107         0.105         0.107
 URE5           0.106         0.105         0.090         0.106
 URE6           0.104         0.104         0.088         0.087         0.104


UNIVARIATE PROPORTIONS AND COUNTS FOR CATEGORICAL VARIABLES

    UDAT
      Category 1    0.159         1571.000
      Category 2    0.841         8339.000
    UDAY
      Category 1    0.019          193.000
      Category 2    0.981         9717.000
    UMON
      Category 1    0.024          234.000
      Category 2    0.976         9676.000
    UYER
      Category 1    0.021          208.000
      Category 2    0.979         9703.000
    UIWR
      Category 1    0.019          193.000
      Category 2    0.012          117.000
      Category 3    0.015          149.000
      Category 4    0.041          406.000
      Category 5    0.094          941.000
      Category 6    0.417         4160.000
      Category 7    0.223         2226.000
      Category 8    0.123         1231.000
      Category 9    0.044          441.000
      Category 10    0.011          108.000
    UDWR
      Category 1    0.059          590.000
      Category 2    0.025          246.000
      Category 3    0.047          473.000
      Category 4    0.104         1037.000
      Category 5    0.171         1710.000
      Category 6    0.398         3973.000
      Category 7    0.113         1127.000
      Category 8    0.056          556.000
      Category 9    0.019          191.000
      Category 10    0.007           69.000
    UHL1
      Category 1    0.036           53.000
      Category 2    0.964         1436.000
    UHL2
      Category 1    0.138          206.000
      Category 2    0.862         1283.000
    UHL3
      Category 1    0.079          117.000
      Category 2    0.921         1372.000
    UHL4
      Category 1    0.132          196.000
      Category 2    0.868         1293.000
    URE2
      Category 1    0.004            5.000
      Category 2    0.996         1407.000
    URE3
      Category 1    0.052           70.000
      Category 2    0.948         1281.000
    URE4
      Category 1    0.119          128.000
      Category 2    0.881          944.000
    URE5
      Category 1    0.130          137.000
      Category 2    0.870          917.000
    URE6
      Category 1    0.110          114.000
      Category 2    0.443          460.000
      Category 3    0.448          465.000


     WARNING:  THE BIVARIATE TABLE OF URE2 AND UDAY HAS AN EMPTY CELL.

     WARNING:  THE BIVARIATE TABLE OF URE2 AND UYER HAS AN EMPTY CELL.

     WARNING:  THE BIVARIATE TABLE OF URE2 AND UHL1 HAS AN EMPTY CELL.

     WARNING:  THE BIVARIATE TABLE OF URE3 AND UYER HAS AN EMPTY CELL.

     WARNING:  THE BIVARIATE TABLE OF URE3 AND URE2 HAS AN EMPTY CELL.

     WARNING:  THE BIVARIATE TABLE OF URE4 AND UYER HAS AN EMPTY CELL.

     WARNING:  THE BIVARIATE TABLE OF URE5 AND UDAY HAS AN EMPTY CELL.

     WARNING:  THE SAMPLE CORRELATION OF URE6 AND URE2 IS  0.987
     DUE TO ONE OR MORE ZERO CELLS IN THEIR BIVARIATE TABLE.
     INFORMATION FROM THESE VARIABLES CAN BE USED TO CREATE ONE NEW VARIABLE.


THE MODEL ESTIMATION TERMINATED NORMALLY

     WARNING:  THE RESIDUAL COVARIANCE MATRIX (THETA) IS NOT POSITIVE DEFINITE.
     THIS COULD INDICATE A NEGATIVE VARIANCE/RESIDUAL VARIANCE FOR AN OBSERVED
